{"links": {"self": {"href": "data/repositories/hoffmanlab/segway/pullrequests/82/comments/54744327.json"}, "code": {"href": "https://api.bitbucket.org/2.0/repositories/hoffmanlab/segway/diff/ericr86/segway:bc8d8fb34886..25bd979b33dd?path=segway%2Frun.py"}, "html": {"href": "#!/hoffmanlab/segway/pull-requests/82/_/diff#comment-54744327"}}, "parent": {"id": 53720878, "links": {"self": {"href": "data/repositories/hoffmanlab/segway/pullrequests/82/comments/53720878.json"}, "html": {"href": "#!/hoffmanlab/segway/pull-requests/82/_/diff#comment-53720878"}}}, "deleted": false, "pullrequest": {"type": "pullrequest", "id": 82, "links": {"self": {"href": "data/repositories/hoffmanlab/segway/pullrequests/82.json"}, "html": {"href": "#!/hoffmanlab/segway/pull-requests/82"}}, "title": "Merge chunks from all genomedata archives for window selection"}, "content": {"raw": "@mmendez12 Could you clarify the issue specifically? Is it the error message? Is it not specific enough?\n\nIf for some reason there are handles opened, the file descriptors will be released back to the OS when the process terminates. Normally CPython will \"close\" the handles automatically (which I agree should not be relied upon) but in this case, it's largely irrelevant since we're reading the files and we're not buffering any data for a write.\n\nAs far as I can tell this won't \"break\" Segway since if an exception did occur while attempting to open the archives, the exception should remain uncaught and cause Segway to terminate.", "markup": "markdown", "html": "<p>@mmendez12 Could you clarify the issue specifically? Is it the error message? Is it not specific enough?</p>\n<p>If for some reason there are handles opened, the file descriptors will be released back to the OS when the process terminates. Normally CPython will \"close\" the handles automatically (which I agree should not be relied upon) but in this case, it's largely irrelevant since we're reading the files and we're not buffering any data for a write.</p>\n<p>As far as I can tell this won't \"break\" Segway since if an exception did occur while attempting to open the archives, the exception should remain uncaught and cause Segway to terminate.</p>", "type": "rendered"}, "created_on": "2018-01-26T16:26:16.365714+00:00", "user": {"display_name": "Eric Roberts", "uuid": "{cd8c1fe0-28ca-45fb-8ef9-48090b42bb80}", "links": {"self": {"href": "https://api.bitbucket.org/2.0/users/%7Bcd8c1fe0-28ca-45fb-8ef9-48090b42bb80%7D"}, "html": {"href": "https://bitbucket.org/%7Bcd8c1fe0-28ca-45fb-8ef9-48090b42bb80%7D/"}, "avatar": {"href": "data/secure.gravatar.com/avatar/17548d71dfb29d015b880f48cfc01ca3d=httpsavatar-management--avatars.us-west-2.prod.public.atl-paas.netinitialsER-5.png"}}, "nickname": "ericr86", "type": "user", "account_id": "557058:c80ca578-03a1-4ac6-b3ee-50372a3fceee"}, "inline": {"to": null, "from": null, "outdated": false, "path": "segway/run.py"}, "updated_on": "2018-01-26T16:26:16.376571+00:00", "type": "pullrequest_comment", "id": 54744327}